Workbook

Sheet All_India_Index_Upto_April23 (1
A1: Sector | B1: Year | C1: Month | D1: Cereals and products | E1: Meat and fish | F1: Egg | G1: Milk and products | H1: Oils and fats | I1: Fruits | J1: Vegetables | K1: Pulses and products | L1: Sugar and Confectionery | M1: Spices | N1: Non-alcoholic beverages | O1: Prepared meals, snacks, sweets etc. | P1: Food and beverages | Q1: Pan, tobacco and intoxicants | R1: Clothing | S1: Footwear | T1: Clothing and footwear | U1: Housing | V1: Fuel and light | W1: Household goods and services | X1: Health | Y1: Transport and communication | Z1: Recreation and amusement | AA1: Education | AB1: Personal care and effects | AC1: Miscellaneous | AD1: General index
A2: Rural | B2: 2013 | C2: January | D2: 107.5 | E2: 106.3 | F2: 108.1 | G2: 104.9 | H2: 106.1 | I2: 103.9 | J2: 101.9 | K2: 106.1 | L2: 106.8 | M2: 103.1 | N2: 104.8 | O2: 106.7 | P2: 105.5 | Q2: 105.1 | R2: 106.5 | S2: 105.8 | T2: 106.4 | U2: NA | V2: 105.5 | W2: 104.8 | X2: 104 | Y2: 103.3 | Z2: 103.4 | AA2: 103.8 | AB2: 104.7 | AC2: 104 | AD2: 105.1
A3: Urban | B3: 2013 | C3: January | D3: 110.5 | E3: 109.1 | F3: 113 | G3: 103.6 | H3: 103.4 | I3: 102.3 | J3: 102.9 | K3: 105.8 | L3: 105.1 | M3: 101.8 | N3: 105.1 | O3: 107.9 | P3: 105.9 | Q3: 105.2 | R3: 105.9 | S3: 105 | T3: 105.8 | U3: 100.3 | V3: 105.4 | W3: 104.8 | X3: 104.1 | Y3: 103.2 | Z3: 102.9 | AA3: 103.5 | AB3: 104.3 | AC3: 103.7 | AD3: 104
A4: Rural+Urban | B4: 2013 | C4: January | D4: 108.4 | E4: 107.3 | F4: 110 | G4: 104.4 | H4: 105.1 | I4: 103.2 | J4: 102.2 | K4: 106 | L4: 106.2 | M4: 102.7 | N4: 104.9 | O4: 107.3 | P4: 105.6 | Q4: 105.1 | R4: 106.3 | S4: 105.5 | T4: 106.2 | U4: 100.3 | V4: 105.5 | W4: 104.8 | X4: 104 | Y4: 103.2 | Z4: 103.1 | AA4: 103.6 | AB4: 104.5 | AC4: 103.9 | AD4: 104.6
A5: Rural | B5: 2013 | C5: February | D5: 109.2 | E5: 108.7 | F5: 110.2 | G5: 105.4 | H5: 106.7 | I5: 104 | J5: 102.4 | K5: 105.9 | L5: 105.7 | M5: 103.1 | N5: 105.1 | O5: 107.7 | P5: 106.3 | Q5: 105.6 | R5: 107.1 | S5: 106.3 | T5: 107 | U5: NA | V5: 106.2 | W5: 105.2 | X5: 104.4 | Y5: 103.9 | Z5: 104 | AA5: 104.1 | AB5: 104.6 | AC5: 104.4 | AD5: 105.8
A6: Urban | B6: 2013 | C6: February | D6: 112.9 | E6: 112.9 | F6: 116.9 | G6: 104 | H6: 103.5 | I6: 103.1 | J6: 104.9 | K6: 104.1 | L6: 103.8 | M6: 102.3 | N6: 106 | O6: 109 | P6: 107.2 | Q6: 106 | R6: 106.6 | S6: 105.5 | T6: 106.4 | U6: 100.4 | V6: 105.7 | W6: 105.2 | X6: 104.7 | Y6: 104.4 | Z6: 103.3 | AA6: 103.7 | AB6: 104.3 | AC6: 104.3 | AD6: 104.7
A7: Rural+Urban | B7: 2013 | C7: February | D7: 110.4 | E7: 110.2 | F7: 112.8 | G7: 104.9 | H7: 105.5 | I7: 103.6 | J7: 103.2 | K7: 105.3 | L7: 105.1 | M7: 102.8 | N7: 105.5 | O7: 108.3 | P7: 106.6 | Q7: 105.7 | R7: 106.9 | S7: 106 | T7: 106.8 | U7: 100.4 | V7: 106 | W7: 105.2 | X7: 104.5 | Y7: 104.2 | Z7: 103.6 | AA7: 103.9 | AB7: 104.5 | AC7: 104.4 | AD7: 105.3
A8: Rural | B8: 2013 | C8: March | D8: 110.2 | E8: 108.8 | F8: 109.9 | G8: 105.6 | H8: 106.2 | I8: 105.7 | J8: 101.4 | K8: 105.7 | L8: 105 | M8: 103.3 | N8: 105.6 | O8: 108.2 | P8: 106.6 | Q8: 106.5 | R8: 107.6 | S8: 106.8 | T8: 107.5 | U8: NA | V8: 106.1 | W8: 105.6 | X8: 104.7 | Y8: 104.6 | Z8: 104 | AA8: 104.3 | AB8: 104.3 | AC8: 104.6 | AD8: 106
A9: Urban | B9: 2013 | C9: March | D9: 113.9 | E9: 111.4 | F9: 113.2 | G9: 104.3 | H9: 102.7 | I9: 104.9 | J9: 103.8 | K9: 103.5 | L9: 102.6 | M9: 102.4 | N9: 107 | O9: 109.8 | P9: 107.3 | Q9: 106.8 | R9: 107.2 | S9: 106 | T9: 107 | U9: 100.4 | V9: 106 | W9: 105.7 | X9: 105.2 | Y9: 105.5 | Z9: 103.5 | AA9: 103.8 | AB9: 104.2 | AC9: 104.9 | AD9: 105
A10: Rural+Urban | B10: 2013 | C10: March | D10: 111.4 | E10: 109.7 | F10: 111.2 | G10: 105.1 | H10: 104.9 | I10: 105.3 | J10: 102.2 | K10: 105 | L10: 104.2 | M10: 103 | N10: 106.2 | O10: 108.9 | P10: 106.9 | Q10: 106.6 | R10: 107.4 | S10: 106.5 | T10: 107.3 | U10: 100.4 | V10: 106.1 | W10: 105.6 | X10: 104.9 | Y10: 105.1 | Z10: 103.7 | AA10: 104 | AB10: 104.3 | AC10: 104.7 | AD10: 105.5
A11: Rural | B11: 2013 | C11: April | D11: 110.2 | E11: 109.5 | F11: 106.9 | G11: 106.3 | H11: 105.7 | I11: 108.3 | J11: 103.4 | K11: 105.7 | L11: 104.2 | M11: 103.2 | N11: 106.5 | O11: 108.8 | P11: 107.1 | Q11: 107.1 | R11: 108.1 | S11: 107.4 | T11: 108 | U11: NA | V11: 106.5 | W11: 106.1 | X11: 105.1 | Y11: 104.4 | Z11: 104.5 | AA11: 104.8 | AB11: 102.7 | AC11: 104.6 | AD11: 106.4
A12: Urban | B12: 2013 | C12: April | D12: 114.6 | E12: 113.4 | F12: 106 | G12: 104.7 | H12: 102.1 | I12: 109.5 | J12: 109.7 | K12: 104.6 | L12: 102 | M12: 103.5 | N12: 108.2 | O12: 110.6 | P12: 108.8 | Q12: 108.5 | R12: 107.9 | S12: 106.4 | T12: 107.7 | U12: 100.5 | V12: 106.4 | W12: 106.5 | X12: 105.7 | Y12: 105 | Z12: 104 | AA12: 105.2 | AB12: 103.2 | AC12: 105.1 | AD12: 105.7
A13: Rural+Urban | B13: 2013 | C13: April | D13: 111.6 | E13: 110.9 | F13: 106.6 | G13: 105.7 | H13: 104.4 | I13: 108.9 | J13: 105.5 | K13: 105.3 | L13: 103.5 | M13: 103.3 | N13: 107.2 | O13: 109.6 | P13: 107.7 | Q13: 107.5 | R13: 108 | S13: 107 | T13: 107.9 | U13: 100.5 | V13: 106.5 | W13: 106.3 | X13: 105.3 | Y13: 104.7 | Z13: 104.2 | AA13: 105 | AB13: 102.9 | AC13: 104.8 | AD13: 106.1
A14: Rural | B14: 2013 | C14: May | D14: 110.9 | E14: 109.8 | F14: 105.9 | G14: 107.5 | H14: 105.3 | I14: 108.1 | J14: 107.3 | K14: 106.1 | L14: 103.7 | M14: 104 | N14: 107.4 | O14: 109.9 | P14: 108.1 | Q14: 108.1 | R14: 108.8 | S14: 107.9 | T14: 108.6 | U14: NA | V14: 107.5 | W14: 106.8 | X14: 105.7 | Y14: 104.1 | Z14: 105 | AA14: 105.5 | AB14: 102.1 | AC14: 104.8 | AD14: 107.2
A15: Urban | B15: 2013 | C15: May | D15: 115.4 | E15: 114.2 | F15: 102.7 | G15: 105.5 | H15: 101.5 | I15: 110.6 | J15: 123.7 | K15: 105.2 | L15: 101.9 | M15: 105 | N15: 109.1 | O15: 111.3 | P15: 111.1 | Q15: 109.8 | R15: 108.5 | S15: 106.7 | T15: 108.3 | U15: 100.5 | V15: 107.2 | W15: 107.1 | X15: 106.2 | Y15: 103.9 | Z15: 104.6 | AA15: 105.7 | AB15: 102.6 | AC15: 104.9 | AD15: 106.6
A16: Rural+Urban | B16: 2013 | C16: May | D16: 112.3 | E16: 111.3 | F16: 104.7 | G16: 106.8 | H16: 103.9 | I16: 109.3 | J16: 112.9 | K16: 105.8 | L16: 103.1 | M16: 104.3 | N16: 108.1 | O16: 110.5 | P16: 109.2 | Q16: 108.6 | R16: 108.7 | S16: 107.4 | T16: 108.5 | U16: 100.5 | V16: 107.4 | W16: 106.9 | X16: 105.9 | Y16: 104 | Z16: 104.8 | AA16: 105.6 | AB16: 102.3 | AC16: 104.8 | AD16: 106.9
A17: Rural | B17: 2013 | C17: June | D17: 112.3 | E17: 112.1 | F17: 108.1 | G17: 108.3 | H17: 105.9 | I17: 109.2 | J17: 118 | K17: 106.8 | L17: 104.1 | M17: 105.4 | N17: 108.2 | O17: 111 | P17: 110.6 | Q17: 109 | R17: 109.7 | S17: 108.8 | T17: 109.5 | U17: NA | V17: 108.5 | W17: 107.5 | X17: 106.3 | Y17: 105 | Z17: 105.6 | AA17: 106.5 | AB17: 102.5 | AC17: 105.5 | AD17: 108.9
A18: Urban | B18: 2013 | C18: June | D18: 117 | E18: 120.1 | F18: 112.5 | G18: 107.3 | H18: 101.3 | I18: 112.4 | J18: 143.6 | K18: 105.4 | L18: 101.4 | M18: 106.4 | N18: 110 | O18: 112.2 | P18: 115 | Q18: 110.9 | R18: 109.2 | S18: 107.2 | T18: 108.9 | U18: 106.6 | V18: 108 | W18: 107.7 | X18: 106.5 | Y18: 105.2 | Z18: 105.2 | AA18: 108.1 | AB18: 103.3 | AC18: 106.1 | AD18: 109.7
A19: Rural+Urban | B19: 2013 | C19: June | D19: 113.8 | E19: 114.9 | F19: 109.8 | G19: 107.9 | H19: 104.2 | I19: 110.7 | J19: 126.7 | K19: 106.3 | L19: 103.2 | M19: 105.7 | N19: 109 | O19: 111.6 | P19: 112.2 | Q19: 109.5 | R19: 109.5 | S19: 108.1 | T19: 109.3 | U19: 106.6 | V19: 108.3 | W19: 107.6 | X19: 106.4 | Y19: 105.1 | Z19: 105.4 | AA19: 107.4 | AB19: 102.8 | AC19: 105.8 | AD19: 109.3
A20: Rural | B20: 2013 | C20: July | D20: 113.4 | E20: 114.9 | F20: 110.5 | G20: 109.3 | H20: 106.2 | I20: 110.3 | J20: 129.2 | K20: 107.1 | L20: 104.3 | M20: 106.4 | N20: 109.1 | O20: 112.1 | P20: 113.1 | Q20: 109.8 | R20: 110.5 | S20: 109.5 | T20: 110.3 | U20: NA | V20: 109.5 | W20: 108.3 | X20: 106.9 | Y20: 106.8 | Z20: 106.4 | AA20: 107.8 | AB20: 102.5 | AC20: 106.5 | AD20: 110.7
A21: Urban | B21: 2013 | C21: July | D21: 117.8 | E21: 119.2 | F21: 114 | G21: 108.3 | H21: 101.1 | I21: 113.2 | J21: 160.9 | K21: 105.1 | L21: 101.3 | M21: 107.5 | N21: 110.4 | O21: 113.1 | P21: 117.5 | Q21: 111.7 | R21: 109.8 | S21: 107.8 | T21: 109.5 | U21: 107.7 | V21: 108.6 | W21: 108.1 | X21: 107.1 | Y21: 107.3 | Z21: 105.9 | AA21: 110.1 | AB21: 103.2 | AC21: 107.3 | AD21: 111.4
A22: Rural+Urban | B22: 2013 | C22: July | D22: 114.8 | E22: 116.4 | F22: 111.9 | G22: 108.9 | H22: 104.3 | I22: 111.7 | J22: 140 | K22: 106.4 | L22: 103.3 | M22: 106.8 | N22: 109.6 | O22: 112.6 | P22: 114.7 | Q22: 110.3 | R22: 110.2 | S22: 108.8 | T22: 110 | U22: 107.7 | V22: 109.2 | W22: 108.2 | X22: 107 | Y22: 107.1 | Z22: 106.1 | AA22: 109.1 | AB22: 102.8 | AC22: 106.9 | AD22: 111
A23: Rural | B23: 2013 | C23: August | D23: 114.3 | E23: 115.4 | F23: 111.1 | G23: 110 | H23: 106.4 | I23: 110.8 | J23: 138.9 | K23: 107.4 | L23: 104.1 | M23: 106.9 | N23: 109.7 | O23: 112.6 | P23: 114.9 | Q23: 110.7 | R23: 111.3 | S23: 110.2 | T23: 111.1 | U23: NA | V23: 109.9 | W23: 108.7 | X23: 107.5 | Y23: 107.8 | Z23: 106.8 | AA23: 108.7 | AB23: 105 | AC23: 107.5 | AD23: 112.1
A24: Urban | B24: 2013 | C24: August | D24: 118.3 | E24: 120.4 | F24: 112.7 | G24: 108.9 | H24: 101.1 | I24: 108.7 | J24: 177 | K24: 104.7 | L24: 101 | M24: 108.5 | N24: 110.9 | O24: 114.3 | P24: 119.6 | Q24: 112.4 | R24: 110.6 | S24: 108.3 | T24: 110.2 | U24: 108.9 | V24: 109.3 | W24: 108.7 | X24: 107.6 | Y24: 108.1 | Z24: 106.5 | AA24: 110.8 | AB24: 106 | AC24: 108.3 | AD24: 112.7
A25: Rural+Urban | B25: 2013 | C25: August | D25: 115.6 | E25: 117.2 | F25: 111.7 | G25: 109.6 | H25: 104.5 | I25: 109.8 | J25: 151.8 | K25: 106.5 | L25: 103.1 | M25: 107.4 | N25: 110.2 | O25: 113.4 | P25: 116.6 | Q25: 111.2 | R25: 111 | S25: 109.4 | T25: 110.7 | U25: 108.9 | V25: 109.7 | W25: 108.7 | X25: 107.5 | Y25: 108 | Z25: 106.6 | AA25: 109.9 | AB25: 105.4 | AC25: 107.9 | AD25: 112.4
A26: Rural | B26: 2013 | C26: September | D26: 115.4 | E26: 115.7 | F26: 111.7 | G26: 111 | H26: 107.4 | I26: 110.9 | J26: 154 | K26: 108.1 | L26: 104.2 | M26: 107.9 | N26: 110.4 | O26: 114 | P26: 117.8 | Q26: 111.7 | R26: 112.7 | S26: 111.4 | T26: 112.5 | U26: NA | V26: 111.1 | W26: 109.6 | X26: 108.3 | Y26: 109.3 | Z26: 107.7 | AA26: 109.8 | AB26: 106.7 | AC26: 108.7 | AD26: 114.2
A27: Urban | B27: 2013 | C27: September | D27: 118.6 | E27: 119.1 | F27: 113.2 | G27: 109.6 | H27: 101.7 | I27: 103.2 | J27: 174.3 | K27: 105.1 | L27: 100.8 | M27: 109.1 | N27: 111.1 | O27: 115.4 | P27: 119.2 | Q27: 112.9 | R27: 111.4 | S27: 109 | T27: 111.1 | U27: 109.7 | V27: 109.5 | W27: 109.6 | X27: 107.9 | Y27: 110.4 | Z27: 107.4 | AA27: 111.2 | AB27: 106.9 | AC27: 109.4 | AD27: 113.2
A28: Rural+Urban | B28: 2013 | C28: September | D28: 116.4 | E28: 116.9 | F28: 112.3 | G28: 110.5 | H28: 105.3 | I28: 107.3 | J28: 160.9 | K28: 107.1 | L28: 103.1 | M28: 108.3 | N28: 110.7 | O28: 114.6 | P28: 118.3 | Q28: 112 | R28: 112.2 | S28: 110.4 | T28: 111.9 | U28: 109.7 | V28: 110.5 | W28: 109.6 | X28: 108.1 | Y28: 109.9 | Z28: 107.5 | AA28: 110.6 | AB28: 106.8 | AC28: 109 | AD28: 113.7
A29: Rural | B29: 2013 | C29: October | D29: 116.3 | E29: 115.4 | F29: 112.6 | G29: 111.7 | H29: 107.7 | I29: 113.2 | J29: 164.9 | K29: 108.3 | L29: 103.9 | M29: 108.2 | N29: 111.1 | O29: 114.9 | P29: 119.8 | Q29: 112.2 | R29: 113.6 | S29: 112.3 | T29: 113.4 | U29: NA | V29: 111.6 | W29: 110.4 | X29: 108.9 | Y29: 109.3 | Z29: 108.3 | AA29: 110.2 | AB29: 107.5 | AC29: 109.1 | AD29: 115.5
A30: Urban | B30: 2013 | C30: October | D30: 118.9 | E30: 118.1 | F30: 114.5 | G30: 110.4 | H30: 102.3 | I30: 106.2 | J30: 183.5 | K30: 105.3 | L30: 100.2 | M30: 109.6 | N30: 111.4 | O30: 116 | P30: 120.8 | Q30: 113.5 | R30: 112.5 | S30: 109.7 | T30: 112 | U30: 110.5 | V30: 109.7 | W30: 110.2 | X30: 108.2 | Y30: 109.7 | Z30: 108 | AA30: 111.3 | AB30: 107.3 | AC30: 109.4 | AD30: 114
A31: Rural+Urban | B31: 2013 | C31: October | D31: 117.1 | E31: 116.3 | F31: 113.3 | G31: 111.2 | H31: 105.7 | I31: 109.9 | J31: 171.2 | K31: 107.3 | L31: 102.7 | M31: 108.7 | N31: 111.2 | O31: 115.4 | P31: 120.2 | Q31: 112.5 | R31: 113.2 | S31: 111.2 | T31: 112.8 | U31: 110.5 | V31: 110.9 | W31: 110.3 | X31: 108.6 | Y31: 109.5 | Z31: 108.1 | AA31: 110.8 | AB31: 107.4 | AC31: 109.2 | AD31: 114.8
A32: Rural | B32: 2013 | C32: November | D32: 117.3 | E32: 114.9 | F32: 116.2 | G32: 112.8 | H32: 108.9 | I32: 116.6 | J32: 178.1 | K32: 109.1 | L32: 103.6 | M32: 109 | N32: 111.8 | O32: 116 | P32: 122.5 | Q32: 112.8 | R32: 114.6 | S32: 113.1 | T32: 114.4 | U32: NA | V32: 112.6 | W32: 111.3 | X32: 109.7 | Y32: 109.6 | Z32: 108.7 | AA32: 111 | AB32: 108.2 | AC32: 109.8 | AD32: 117.4
A33: Urban | B33: 2013 | C33: November | D33: 119.8 | E33: 116.3 | F33: 122.6 | G33: 112 | H33: 103.2 | I33: 110 | J33: 192.8 | K33: 106.3 | L33: 99.5 | M33: 110.3 | N33: 111.8 | O33: 117.1 | P33: 122.9 | Q33: 114.1 | R33: 113.5 | S33: 110.3 | T33: 113 | U33: 111.1 | V33: 110 | W33: 110.9 | X33: 108.6 | Y33: 109.5 | Z33: 108.5 | AA33: 111.3 | AB33: 107.9 | AC33: 109.6 | AD33: 115
A34: Rural+Urban | B34: 2013 | C34: November | D34: 118.1 | E34: 115.4 | F34: 118.7 | G34: 112.5 | H34: 106.8 | I34: 113.5 | J34: 183.1 | K34: 108.2 | L34: 102.2 | M34: 109.4 | N34: 111.8 | O34: 116.5 | P34: 122.6 | Q34: 113.1 | R34: 114.2 | S34: 111.9 | T34: 113.8 | U34: 111.1 | V34: 111.6 | W34: 111.1 | X34: 109.3 | Y34: 109.5 | Z34: 108.6 | AA34: 111.2 | AB34: 108.1 | AC34: 109.7 | AD34: 116.3
A35: Rural | B35: 2013 | C35: December | D35: 118.4 | E35: 115.9 | F35: 120.4 | G35: 113.8 | H35: 109.5 | I35: 115.5 | J35: 145.7 | K35: 109.5 | L35: 102.9 | M35: 109.8 | N35: 112.1 | O35: 116.8 | P35: 118.7 | Q35: 113.6 | R35: 115.8 | S35: 114 | T35: 115.5 | U35: NA | V35: 112.8 | W35: 112.1 | X35: 110.1 | Y35: 109.9 | Z35: 109.2 | AA35: 111.6 | AB35: 108.1 | AC35: 110.1 | AD35: 115.5
A36: Urban | B36: 2013 | C36: December | D36: 120.5 | E36: 118.1 | F36: 128.5 | G36: 112.8 | H36: 103.4 | I36: 110.7 | J36: 144.8 | K36: 107.1 | L36: 98.6 | M36: 111.9 | N36: 112.1 | O36: 118.1 | P36: 117.8 | Q36: 115 | R36: 114.2 | S36: 110.9 | T36: 113.7 | U36: 110.7 | V36: 110.4 | W36: 111.3 | X36: 109 | Y36: 109.7 | Z36: 108.9 | AA36: 111.4 | AB36: 107.7 | AC36: 109.8 | AD36: 113.3
A37: Rural+Urban | B37: 2013 | C37: December | D37: 119.1 | E37: 116.7 | F37: 123.5 | G37: 113.4 | H37: 107.3 | I37: 113.3 | J37: 145.4 | K37: 108.7 | L37: 101.5 | M37: 110.5 | N37: 112.1 | O37: 117.4 | P37: 118.4 | Q37: 114 | R37: 115.2 | S37: 112.7 | T37: 114.8 | U37: 110.7 | V37: 111.9 | W37: 111.7 | X37: 109.7 | Y37: 109.8 | Z37: 109 | AA37: 111.5 | AB37: 107.9 | AC37: 110 | AD37: 114.5
A38: Rural | B38: 2014 | C38: January | D38: 118.9 | E38: 117.1 | F38: 120.5 | G38: 114.4 | H38: 109 | I38: 115.5 | J38: 123.9 | K38: 109.6 | L38: 101.8 | M38: 110.2 | N38: 112.4 | O38: 117.3 | P38: 116 | Q38: 114 | R38: 116.5 | S38: 114.5 | T38: 116.2 | U38: NA | V38: 113 | W38: 112.6 | X38: 110.6 | Y38: 110.5 | Z38: 109.6 | AA38: 111.8 | AB38: 108.3 | AC38: 110.6 | AD38: 114.2
A39: Urban | B39: 2014 | C39: January | D39: 121.2 | E39: 122 | F39: 129.9 | G39: 113.6 | H39: 102.9 | I39: 112.1 | J39: 118.9 | K39: 107.5 | L39: 96.9 | M39: 112.7 | N39: 112.1 | O39: 119 | P39: 115.5 | Q39: 115.7 | R39: 114.8 | S39: 111.3 | T39: 114.3 | U39: 111.6 | V39: 111 | W39: 111.9 | X39: 109.7 | Y39: 110.8 | Z39: 109.8 | AA39: 111.5 | AB39: 108 | AC39: 110.5 | AD39: 112.9
A40: Rural+Urban | B40: 2014 | C40: January | D40: 119.6 | E40: 118.8 | F40: 124.1 | G40: 114.1 | H40: 106.8 | I40: 113.9 | J40: 122.2 | K40: 108.9 | L40: 100.2 | M40: 111 | N40: 112.3 | O40: 118.1 | P40: 115.8 | Q40: 114.5 | R40: 115.8 | S40: 113.2 | T40: 115.4 | U40: 111.6 | V40: 112.2 | W40: 112.3 | X40: 110.3 | Y40: 110.7 | Z40: 109.7 | AA40: 111.6 | AB40: 108.2 | AC40: 110.6 | AD40: 113.6
...

Sheet Main Data
A1: Mean | B1: =AVERAGE(B7:B378) -> 2017.7097 | C1: =AVERAGE(C7:C378) -> #DIV/0! | D1: =AVERAGE(D7:D378) -> 136.68591 | F1: =AVERAGE(F7:F378) -> 156.26475 | H1: =AVERAGE(H7:H378) -> 140.87737 | I1: =AVERAGE(I7:I378) -> 140.42715 | J1: =AVERAGE(J7:J378) -> 132.14216 | K1: =AVERAGE(K7:K378) -> 140.88768 | L1: =AVERAGE(L7:L378) -> 155.83987 | M1: =AVERAGE(M7:M378) -> 141.47961 | N1: =AVERAGE(N7:N378) -> 110.96062 | O1: =AVERAGE(O7:O378) -> 144.62012 | ... Q1: =AVERAGE(Q7:Q378) -> 149.08716 | S1: =AVERAGE(S7:S378) -> 142.59418 | T1: =AVERAGE(T7:T378) -> 155.38579 | V1: =AVERAGE(V7:V378) -> 142.66366 | X1: =AVERAGE(X7:X378) -> 135.97732 | Z1: =AVERAGE(Z7:Z378) -> 141.67432 | AB1: =AVERAGE(AB7:AB378) -> 139.2561 | AE1: =AVERAGE(AE7:AE378) -> 136.51003 | AG1: =AVERAGE(AG7:AG378) -> 136.68689 | AI1: =AVERAGE(AI7:AI378) -> 138.5168 | AJ1: =AVERAGE(AJ7:AJ378) -> 127.17049 | AL1: =AVERAGE(AL7:AL378) -> 133.8918 | AN1: =AVERAGE(AN7:AN378) -> 141.13115 | AP1: =AVERAGE(AP7:AP378) -> 133.35 | AR1: =AVERAGE(AR7:AR378) -> 134.23579 | AT1: =AVERAGE(AT7:AT378) -> 139.56448
A2: Median | B2: =MEDIAN(B7:B378) -> 2018 | C2: =MEDIAN(C7:C378) -> #NUM! | D2: =MEDIAN(D7:D378) -> 135.9 | F2: =MEDIAN(F7:F378) -> 144.2 | H2: =MEDIAN(H7:H378) -> 135.75 | I2: =MEDIAN(I7:I378) -> 141.15 | J2: =MEDIAN(J7:J378) -> 120.6 | K2: =MEDIAN(K7:K378) -> 141.5 | L2: =MEDIAN(L7:L378) -> 153.6 | M2: =MEDIAN(M7:M378) -> 139.65 | N2: =MEDIAN(N7:N378) -> 113.4 | O2: =MEDIAN(O7:O378) -> 139.6 | ... Q2: =MEDIAN(Q7:Q378) -> 149.35 | S2: =MEDIAN(S7:S378) -> 138.65 | T2: =MEDIAN(T7:T378) -> 155.6 | V2: =MEDIAN(V7:V378) -> 142.85 | X2: =MEDIAN(X7:X378) -> 133.1 | Z2: =MEDIAN(Z7:Z378) -> 141.5 | AB2: =MEDIAN(AB7:AB378) -> 141.3 | AE2: =MEDIAN(AE7:AE378) -> 132.2 | AG2: =MEDIAN(AG7:AG378) -> 135 | AI2: =MEDIAN(AI7:AI378) -> 133.6 | AJ2: =MEDIAN(AJ7:AJ378) -> 119.7 | AL2: =MEDIAN(AL7:AL378) -> 129.85 | AN2: =MEDIAN(AN7:AN378) -> 139.95 | AP2: =MEDIAN(AP7:AP378) -> 127.65 | AR2: =MEDIAN(AR7:AR378) -> 129.65 | AT2: =MEDIAN(AT7:AT378) -> 137.15
A3: Mode | B3: =MODE(B7:B378) -> 2013 | C3: =MODE(C7:C378) -> #N/A | D3: =MODE(D7:D378) -> 124 | F3: =MODE(F7:F378) -> 143.7 | H3: =MODE(H7:H378) -> 117.8 | I3: =MODE(I7:I378) -> 153.3 | J3: =MODE(J7:J378) -> 118.1 | K3: =MODE(K7:K378) -> 147.2 | L3: =MODE(L7:L378) -> 129.2 | M3: =MODE(M7:M378) -> 164 | N3: =MODE(N7:N378) -> 121.9 | O3: =MODE(O7:O378) -> 135.6 | ... Q3: =MODE(Q7:Q378) -> 161.8 | S3: =MODE(S7:S378) -> 131.8 | T3: =MODE(T7:T378) -> 196.5 | V3: =MODE(V7:V378) -> 115.8 | X3: =MODE(X7:X378) -> 146.1 | Z3: =MODE(Z7:Z378) -> 129 | AB3: =MODE(AB7:AB378) -> 100.4 | AE3: =MODE(AE7:AE378) -> 113.4 | AG3: =MODE(AG7:AG378) -> 146.4 | AI3: =MODE(AI7:AI378) -> 109.7 | AJ3: =MODE(AJ7:AJ378) -> 109.3 | AL3: =MODE(AL7:AL378) -> 104 | AN3: =MODE(AN7:AN378) -> 155.5 | AP3: =MODE(AP7:AP378) -> 104.3 | AR3: =MODE(AR7:AR378) -> 113.7 | AT3: =MODE(AT7:AT378) -> 114.2
A6: Sector | B6: Year | C6: Month | D6: Cereals and products | F6: Meat and fish | H6: Egg | I6: Milk and products | J6: Oils and fats | K6: Fruits | L6: Vegetables | M6: Pulses and products | N6: Sugar and Confectionery | O6: Spices | P6: Non-alcoholic beverages | Q6: Prepared meals, snacks, sweets etc. | S6: Food and beverages | T6: Pan, tobacco and intoxicants | V6: Clothing | X6: Footwear | Z6: Clothing and footwear | AB6: Housing | AE6: Fuel and light | AG6: Household goods and services | AI6: Health | AJ6: Transport and communication | AL6: Recreation and amusement | AN6: Education | AP6: Personal care and effects | AR6: Miscellaneous | AT6: General index
A7: Rural | B7: 2013 | C7: January | D7: 107.5 | F7: 106.3 | H7: 108.1 | I7: 104.9 | J7: 106.1 | K7: 103.9 | L7: 101.9 | M7: 106.1 | N7: 106.8 | O7: 103.1 | P7: 104.8 | Q7: 106.7 | S7: 105.5 | T7: 105.1 | V7: 106.5 | X7: 105.8 | Z7: 106.4 | AB7: NA | AC7: =AB8 -> 100.3 | AE7: 105.5 | AG7: 104.8 | AI7: 104 | AJ7: 103.3 | AL7: 103.4 | AN7: 103.8 | AP7: 104.7 | AR7: 104 | AT7: 105.1
A8: Urban | B8: 2013 | C8: January | D8: 110.5 | F8: 109.1 | H8: 113 | I8: 103.6 | J8: 103.4 | K8: 102.3 | L8: 102.9 | M8: 105.8 | N8: 105.1 | O8: 101.8 | P8: 105.1 | Q8: 107.9 | S8: 105.9 | T8: 105.2 | V8: 105.9 | X8: 105 | Z8: 105.8 | AB8: 100.3 | AC8: =AB8 -> 100.3 | AE8: 105.4 | AG8: 104.8 | AI8: 104.1 | AJ8: 103.2 | AL8: 102.9 | AN8: 103.5 | AP8: 104.3 | AR8: 103.7 | AT8: 104
A9: Rural+Urban | B9: 2013 | C9: January | D9: 108.4 | F9: 107.3 | H9: 110 | I9: 104.4 | J9: 105.1 | K9: 103.2 | L9: 102.2 | M9: 106 | N9: 106.2 | O9: 102.7 | P9: 104.9 | Q9: 107.3 | S9: 105.6 | T9: 105.1 | V9: 106.3 | X9: 105.5 | Z9: 106.2 | AB9: 100.3 | AC9: =AB9 -> 100.3 | AE9: 105.5 | AG9: 104.8 | AI9: 104 | AJ9: 103.2 | AL9: 103.1 | AN9: 103.6 | AP9: 104.5 | AR9: 103.9 | AT9: 104.6
A10: Rural | B10: 2013 | C10: February | D10: 109.2 | F10: 108.7 | H10: 110.2 | I10: 105.4 | J10: 106.7 | K10: 104 | L10: 102.4 | M10: 105.9 | N10: 105.7 | O10: 103.1 | P10: 105.1 | Q10: 107.7 | S10: 106.3 | T10: 105.6 | V10: 107.1 | X10: 106.3 | Z10: 107 | AB10: NA | AC10: =AB11 -> 100.4 | AE10: 106.2 | AG10: 105.2 | AI10: 104.4 | AJ10: 103.9 | AL10: 104 | AN10: 104.1 | AP10: 104.6 | AR10: 104.4 | AT10: 105.8
A11: Urban | B11: 2013 | C11: February | D11: 112.9 | F11: 112.9 | H11: 116.9 | I11: 104 | J11: 103.5 | K11: 103.1 | L11: 104.9 | M11: 104.1 | N11: 103.8 | O11: 102.3 | P11: 106 | Q11: 109 | S11: 107.2 | T11: 106 | V11: 106.6 | X11: 105.5 | Z11: 106.4 | AB11: 100.4 | AC11: =AB11 -> 100.4 | AE11: 105.7 | AG11: 105.2 | AI11: 104.7 | AJ11: 104.4 | AL11: 103.3 | AN11: 103.7 | AP11: 104.3 | AR11: 104.3 | AT11: 104.7
A12: Rural+Urban | B12: 2013 | C12: February | D12: 110.4 | F12: 110.2 | H12: 112.8 | I12: 104.9 | J12: 105.5 | K12: 103.6 | L12: 103.2 | M12: 105.3 | N12: 105.1 | O12: 102.8 | P12: 105.5 | Q12: 108.3 | S12: 106.6 | T12: 105.7 | V12: 106.9 | X12: 106 | Z12: 106.8 | AB12: 100.4 | AC12: =AB12 -> 100.4 | AE12: 106 | AG12: 105.2 | AI12: 104.5 | AJ12: 104.2 | AL12: 103.6 | AN12: 103.9 | AP12: 104.5 | AR12: 104.4 | AT12: 105.3
A13: Rural | B13: 2013 | C13: March | D13: 110.2 | F13: 108.8 | H13: 109.9 | I13: 105.6 | J13: 106.2 | K13: 105.7 | L13: 101.4 | M13: 105.7 | N13: 105 | O13: 103.3 | P13: 105.6 | Q13: 108.2 | S13: 106.6 | T13: 106.5 | V13: 107.6 | X13: 106.8 | Z13: 107.5 | AB13: NA | AC13: =AB14 -> 100.4 | AE13: 106.1 | AG13: 105.6 | AI13: 104.7 | AJ13: 104.6 | AL13: 104 | AN13: 104.3 | AP13: 104.3 | AR13: 104.6 | AT13: 106
A14: Urban | B14: 2013 | C14: March | D14: 113.9 | F14: 111.4 | H14: 113.2 | I14: 104.3 | J14: 102.7 | K14: 104.9 | L14: 103.8 | M14: 103.5 | N14: 102.6 | O14: 102.4 | P14: 107 | Q14: 109.8 | S14: 107.3 | T14: 106.8 | V14: 107.2 | X14: 106 | Z14: 107 | AB14: 100.4 | AC14: =AB14 -> 100.4 | AE14: 106 | AG14: 105.7 | AI14: 105.2 | AJ14: 105.5 | AL14: 103.5 | AN14: 103.8 | AP14: 104.2 | AR14: 104.9 | AT14: 105
A15: Rural+Urban | B15: 2013 | C15: March | D15: 111.4 | F15: 109.7 | H15: 111.2 | I15: 105.1 | J15: 104.9 | K15: 105.3 | L15: 102.2 | M15: 105 | N15: 104.2 | O15: 103 | P15: 106.2 | Q15: 108.9 | S15: 106.9 | T15: 106.6 | V15: 107.4 | X15: 106.5 | Z15: 107.3 | AB15: 100.4 | AC15: =AB15 -> 100.4 | AE15: 106.1 | AG15: 105.6 | AI15: 104.9 | AJ15: 105.1 | AL15: 103.7 | AN15: 104 | AP15: 104.3 | AR15: 104.7 | AT15: 105.5
A16: Rural | B16: 2013 | C16: April | D16: 110.2 | F16: 109.5 | H16: 106.9 | I16: 106.3 | J16: 105.7 | K16: 108.3 | L16: 103.4 | M16: 105.7 | N16: 104.2 | O16: 103.2 | P16: 106.5 | Q16: 108.8 | S16: 107.1 | T16: 107.1 | V16: 108.1 | X16: 107.4 | Z16: 108 | AB16: NA | AC16: =AB17 -> 100.5 | AE16: 106.5 | AG16: 106.1 | AI16: 105.1 | AJ16: 104.4 | AL16: 104.5 | AN16: 104.8 | AP16: 102.7 | AR16: 104.6 | AT16: 106.4
A17: Urban | B17: 2013 | C17: April | D17: 114.6 | F17: 113.4 | H17: 106 | I17: 104.7 | J17: 102.1 | K17: 109.5 | L17: 109.7 | M17: 104.6 | N17: 102 | O17: 103.5 | P17: 108.2 | Q17: 110.6 | S17: 108.8 | T17: 108.5 | V17: 107.9 | X17: 106.4 | Z17: 107.7 | AB17: 100.5 | AC17: =AB17 -> 100.5 | AE17: 106.4 | AG17: 106.5 | AI17: 105.7 | AJ17: 105 | AL17: 104 | AN17: 105.2 | AP17: 103.2 | AR17: 105.1 | AT17: 105.7
A18: Rural+Urban | B18: 2013 | C18: April | D18: 111.6 | F18: 110.9 | H18: 106.6 | I18: 105.7 | J18: 104.4 | K18: 108.9 | L18: 105.5 | M18: 105.3 | N18: 103.5 | O18: 103.3 | P18: 107.2 | Q18: 109.6 | S18: 107.7 | T18: 107.5 | V18: 108 | X18: 107 | Z18: 107.9 | AB18: 100.5 | AC18: =AB18 -> 100.5 | AE18: 106.5 | AG18: 106.3 | AI18: 105.3 | AJ18: 104.7 | AL18: 104.2 | AN18: 105 | AP18: 102.9 | AR18: 104.8 | AT18: 106.1
A19: Rural | B19: 2013 | C19: May | D19: 110.9 | F19: 109.8 | H19: 105.9 | I19: 107.5 | J19: 105.3 | K19: 108.1 | L19: 107.3 | M19: 106.1 | N19: 103.7 | O19: 104 | P19: 107.4 | Q19: 109.9 | S19: 108.1 | T19: 108.1 | V19: 108.8 | X19: 107.9 | Z19: 108.6 | AB19: NA | AC19: =AB20 -> 100.5 | AE19: 107.5 | AG19: 106.8 | AI19: 105.7 | AJ19: 104.1 | AL19: 105 | AN19: 105.5 | AP19: 102.1 | AR19: 104.8 | AT19: 107.2
A20: Urban | B20: 2013 | C20: May | D20: 115.4 | F20: 114.2 | H20: 102.7 | I20: 105.5 | J20: 101.5 | K20: 110.6 | L20: 123.7 | M20: 105.2 | N20: 101.9 | O20: 105 | P20: 109.1 | Q20: 111.3 | S20: 111.1 | T20: 109.8 | V20: 108.5 | X20: 106.7 | Z20: 108.3 | AB20: 100.5 | AC20: =AB20 -> 100.5 | AE20: 107.2 | AG20: 107.1 | AI20: 106.2 | AJ20: 103.9 | AL20: 104.6 | AN20: 105.7 | AP20: 102.6 | AR20: 104.9 | AT20: 106.6
A21: Rural+Urban | B21: 2013 | C21: May | D21: 112.3 | F21: 111.3 | H21: 104.7 | I21: 106.8 | J21: 103.9 | K21: 109.3 | L21: 112.9 | M21: 105.8 | N21: 103.1 | O21: 104.3 | P21: 108.1 | Q21: 110.5 | S21: 109.2 | T21: 108.6 | V21: 108.7 | X21: 107.4 | Z21: 108.5 | AB21: 100.5 | AC21: =AB21 -> 100.5 | AE21: 107.4 | AG21: 106.9 | AI21: 105.9 | AJ21: 104 | AL21: 104.8 | AN21: 105.6 | AP21: 102.3 | AR21: 104.8 | AT21: 106.9
A22: Rural | B22: 2013 | C22: June | D22: 112.3 | F22: 112.1 | H22: 108.1 | I22: 108.3 | J22: 105.9 | K22: 109.2 | L22: 118 | M22: 106.8 | N22: 104.1 | O22: 105.4 | P22: 108.2 | Q22: 111 | S22: 110.6 | T22: 109 | V22: 109.7 | X22: 108.8 | Z22: 109.5 | AB22: NA | AC22: =AB23 -> 106.6 | AE22: 108.5 | AG22: 107.5 | AI22: 106.3 | AJ22: 105 | AL22: 105.6 | AN22: 106.5 | AP22: 102.5 | AR22: 105.5 | AT22: 108.9
A23: Urban | B23: 2013 | C23: June | D23: 117 | F23: 120.1 | H23: 112.5 | I23: 107.3 | J23: 101.3 | K23: 112.4 | L23: 143.6 | M23: 105.4 | N23: 101.4 | O23: 106.4 | P23: 110 | Q23: 112.2 | S23: 115 | T23: 110.9 | V23: 109.2 | X23: 107.2 | Z23: 108.9 | AB23: 106.6 | AC23: =AB23 -> 106.6 | AE23: 108 | AG23: 107.7 | AI23: 106.5 | AJ23: 105.2 | AL23: 105.2 | AN23: 108.1 | AP23: 103.3 | AR23: 106.1 | AT23: 109.7
A24: Rural+Urban | B24: 2013 | C24: June | D24: 113.8 | F24: 114.9 | H24: 109.8 | I24: 107.9 | J24: 104.2 | K24: 110.7 | L24: 126.7 | M24: 106.3 | N24: 103.2 | O24: 105.7 | P24: 109 | Q24: 111.6 | S24: 112.2 | T24: 109.5 | V24: 109.5 | X24: 108.1 | Z24: 109.3 | AB24: 106.6 | AC24: =AB24 -> 106.6 | AE24: 108.3 | AG24: 107.6 | AI24: 106.4 | AJ24: 105.1 | AL24: 105.4 | AN24: 107.4 | AP24: 102.8 | AR24: 105.8 | AT24: 109.3
A25: Rural | B25: 2013 | C25: July | D25: 113.4 | F25: 114.9 | H25: 110.5 | I25: 109.3 | J25: 106.2 | K25: 110.3 | L25: 129.2 | M25: 107.1 | N25: 104.3 | O25: 106.4 | P25: 109.1 | Q25: 112.1 | S25: 113.1 | T25: 109.8 | V25: 110.5 | X25: 109.5 | Z25: 110.3 | AB25: NA | AC25: =AB26 -> 107.7 | AE25: 109.5 | AG25: 108.3 | AI25: 106.9 | AJ25: 106.8 | AL25: 106.4 | AN25: 107.8 | AP25: 102.5 | AR25: 106.5 | AT25: 110.7
A26: Urban | B26: 2013 | C26: July | D26: 117.8 | F26: 119.2 | H26: 114 | I26: 108.3 | J26: 101.1 | K26: 113.2 | L26: 160.9 | M26: 105.1 | N26: 101.3 | O26: 107.5 | P26: 110.4 | Q26: 113.1 | S26: 117.5 | T26: 111.7 | V26: 109.8 | X26: 107.8 | Z26: 109.5 | AB26: 107.7 | AC26: =AB26 -> 107.7 | AE26: 108.6 | AG26: 108.1 | AI26: 107.1 | AJ26: 107.3 | AL26: 105.9 | AN26: 110.1 | AP26: 103.2 | AR26: 107.3 | AT26: 111.4
A27: Rural+Urban | B27: 2013 | C27: July | D27: 114.8 | F27: 116.4 | H27: 111.9 | I27: 108.9 | J27: 104.3 | K27: 111.7 | L27: 140 | M27: 106.4 | N27: 103.3 | O27: 106.8 | P27: 109.6 | Q27: 112.6 | S27: 114.7 | T27: 110.3 | V27: 110.2 | X27: 108.8 | Z27: 110 | AB27: 107.7 | AC27: =AB27 -> 107.7 | AE27: 109.2 | AG27: 108.2 | AI27: 107 | AJ27: 107.1 | AL27: 106.1 | AN27: 109.1 | AP27: 102.8 | AR27: 106.9 | AT27: 111
A28: Rural | B28: 2013 | C28: August | D28: 114.3 | F28: 115.4 | H28: 111.1 | I28: 110 | J28: 106.4 | K28: 110.8 | L28: 138.9 | M28: 107.4 | N28: 104.1 | O28: 106.9 | P28: 109.7 | Q28: 112.6 | S28: 114.9 | T28: 110.7 | V28: 111.3 | X28: 110.2 | Z28: 111.1 | AB28: NA | AC28: =AB29 -> 108.9 | AE28: 109.9 | AG28: 108.7 | AI28: 107.5 | AJ28: 107.8 | AL28: 106.8 | AN28: 108.7 | AP28: 105 | AR28: 107.5 | AT28: 112.1
A29: Urban | B29: 2013 | C29: August | D29: 118.3 | F29: 120.4 | H29: 112.7 | I29: 108.9 | J29: 101.1 | K29: 108.7 | L29: 177 | M29: 104.7 | N29: 101 | O29: 108.5 | P29: 110.9 | Q29: 114.3 | S29: 119.6 | T29: 112.4 | V29: 110.6 | X29: 108.3 | Z29: 110.2 | AB29: 108.9 | AC29: =AB29 -> 108.9 | AE29: 109.3 | AG29: 108.7 | AI29: 107.6 | AJ29: 108.1 | AL29: 106.5 | AN29: 110.8 | AP29: 106 | AR29: 108.3 | AT29: 112.7
A30: Rural+Urban | B30: 2013 | C30: August | D30: 115.6 | F30: 117.2 | H30: 111.7 | I30: 109.6 | J30: 104.5 | K30: 109.8 | L30: 151.8 | M30: 106.5 | N30: 103.1 | O30: 107.4 | P30: 110.2 | Q30: 113.4 | S30: 116.6 | T30: 111.2 | V30: 111 | X30: 109.4 | Z30: 110.7 | AB30: 108.9 | AC30: =AB30 -> 108.9 | AE30: 109.7 | AG30: 108.7 | AI30: 107.5 | AJ30: 108 | AL30: 106.6 | AN30: 109.9 | AP30: 105.4 | AR30: 107.9 | AT30: 112.4
A31: Rural | B31: 2013 | C31: September | D31: 115.4 | F31: 115.7 | H31: 111.7 | I31: 111 | J31: 107.4 | K31: 110.9 | L31: 154 | M31: 108.1 | N31: 104.2 | O31: 107.9 | P31: 110.4 | Q31: 114 | S31: 117.8 | T31: 111.7 | V31: 112.7 | X31: 111.4 | Z31: 112.5 | AB31: NA | AC31: =AB32 -> 109.7 | AE31: 111.1 | AG31: 109.6 | AI31: 108.3 | AJ31: 109.3 | AL31: 107.7 | AN31: 109.8 | AP31: 106.7 | AR31: 108.7 | AT31: 114.2
A32: Urban | B32: 2013 | C32: September | D32: 118.6 | F32: 119.1 | H32: 113.2 | I32: 109.6 | J32: 101.7 | K32: 103.2 | L32: 174.3 | M32: 105.1 | N32: 100.8 | O32: 109.1 | P32: 111.1 | Q32: 115.4 | S32: 119.2 | T32: 112.9 | V32: 111.4 | X32: 109 | Z32: 111.1 | AB32: 109.7 | AC32: =AB32 -> 109.7 | AE32: 109.5 | AG32: 109.6 | AI32: 107.9 | AJ32: 110.4 | AL32: 107.4 | AN32: 111.2 | AP32: 106.9 | AR32: 109.4 | AT32: 113.2
A33: Rural+Urban | B33: 2013 | C33: September | D33: 116.4 | F33: 116.9 | H33: 112.3 | I33: 110.5 | J33: 105.3 | K33: 107.3 | L33: 160.9 | M33: 107.1 | N33: 103.1 | O33: 108.3 | P33: 110.7 | Q33: 114.6 | S33: 118.3 | T33: 112 | V33: 112.2 | X33: 110.4 | Z33: 111.9 | AB33: 109.7 | AC33: =AB33 -> 109.7 | AE33: 110.5 | AG33: 109.6 | AI33: 108.1 | AJ33: 109.9 | AL33: 107.5 | AN33: 110.6 | AP33: 106.8 | AR33: 109 | AT33: 113.7
A34: Rural | B34: 2013 | C34: October | D34: 116.3 | F34: 115.4 | H34: 112.6 | I34: 111.7 | J34: 107.7 | K34: 113.2 | L34: 164.9 | M34: 108.3 | N34: 103.9 | O34: 108.2 | P34: 111.1 | Q34: 114.9 | S34: 119.8 | T34: 112.2 | V34: 113.6 | X34: 112.3 | Z34: 113.4 | AB34: NA | AC34: =AB35 -> 110.5 | AE34: 111.6 | AG34: 110.4 | AI34: 108.9 | AJ34: 109.3 | AL34: 108.3 | AN34: 110.2 | AP34: 107.5 | AR34: 109.1 | AT34: 115.5
A35: Urban | B35: 2013 | C35: October | D35: 118.9 | F35: 118.1 | H35: 114.5 | I35: 110.4 | J35: 102.3 | K35: 106.2 | L35: 183.5 | M35: 105.3 | N35: 100.2 | O35: 109.6 | P35: 111.4 | Q35: 116 | S35: 120.8 | T35: 113.5 | V35: 112.5 | X35: 109.7 | Z35: 112 | AB35: 110.5 | AC35: =AB35 -> 110.5 | AE35: 109.7 | AG35: 110.2 | AI35: 108.2 | AJ35: 109.7 | AL35: 108 | AN35: 111.3 | AP35: 107.3 | AR35: 109.4 | AT35: 114
A36: Rural+Urban | B36: 2013 | C36: October | D36: 117.1 | F36: 116.3 | H36: 113.3 | I36: 111.2 | J36: 105.7 | K36: 109.9 | L36: 171.2 | M36: 107.3 | N36: 102.7 | O36: 108.7 | P36: 111.2 | Q36: 115.4 | S36: 120.2 | T36: 112.5 | V36: 113.2 | X36: 111.2 | Z36: 112.8 | AB36: 110.5 | AC36: =AB36 -> 110.5 | AE36: 110.9 | AG36: 110.3 | AI36: 108.6 | AJ36: 109.5 | AL36: 108.1 | AN36: 110.8 | AP36: 107.4 | AR36: 109.2 | AT36: 114.8
A37: Rural | B37: 2013 | C37: November | D37: 117.3 | F37: 114.9 | H37: 116.2 | I37: 112.8 | J37: 108.9 | K37: 116.6 | L37: 178.1 | M37: 109.1 | N37: 103.6 | O37: 109 | P37: 111.8 | Q37: 116 | S37: 122.5 | T37: 112.8 | V37: 114.6 | X37: 113.1 | Z37: 114.4 | AB37: NA | AC37: =AB38 -> 111.1 | AE37: 112.6 | AG37: 111.3 | AI37: 109.7 | AJ37: 109.6 | AL37: 108.7 | AN37: 111 | AP37: 108.2 | AR37: 109.8 | AT37: 117.4
A38: Urban | B38: 2013 | C38: November | D38: 119.8 | F38: 116.3 | H38: 122.6 | I38: 112 | J38: 103.2 | K38: 110 | L38: 192.8 | M38: 106.3 | N38: 99.5 | O38: 110.3 | P38: 111.8 | Q38: 117.1 | S38: 122.9 | T38: 114.1 | V38: 113.5 | X38: 110.3 | Z38: 113 | AB38: 111.1 | AC38: =AB38 -> 111.1 | AE38: 110 | AG38: 110.9 | AI38: 108.6 | AJ38: 109.5 | AL38: 108.5 | AN38: 111.3 | AP38: 107.9 | AR38: 109.6 | AT38: 115
A39: Rural+Urban | B39: 2013 | C39: November | D39: 118.1 | F39: 115.4 | H39: 118.7 | I39: 112.5 | J39: 106.8 | K39: 113.5 | L39: 183.1 | M39: 108.2 | N39: 102.2 | O39: 109.4 | P39: 111.8 | Q39: 116.5 | S39: 122.6 | T39: 113.1 | V39: 114.2 | X39: 111.9 | Z39: 113.8 | AB39: 111.1 | AC39: =AB39 -> 111.1 | AE39: 111.6 | AG39: 111.1 | AI39: 109.3 | AJ39: 109.5 | AL39: 108.6 | AN39: 111.2 | AP39: 108.1 | AR39: 109.7 | AT39: 116.3
A40: Rural | B40: 2013 | C40: December | D40: 118.4 | F40: 115.9 | H40: 120.4 | I40: 113.8 | J40: 109.5 | K40: 115.5 | L40: 145.7 | M40: 109.5 | N40: 102.9 | O40: 109.8 | P40: 112.1 | Q40: 116.8 | S40: 118.7 | T40: 113.6 | V40: 115.8 | X40: 114 | Z40: 115.5 | AB40: NA | AC40: =AB41 -> 110.7 | AE40: 112.8 | AG40: 112.1 | AI40: 110.1 | AJ40: 109.9 | AL40: 109.2 | AN40: 111.6 | AP40: 108.1 | AR40: 110.1 | AT40: 115.5
A41: Urban | B41: 2013 | C41: December | D41: 120.5 | F41: 118.1 | H41: 128.5 | I41: 112.8 | J41: 103.4 | K41: 110.7 | L41: 144.8 | M41: 107.1 | N41: 98.6 | O41: 111.9 | P41: 112.1 | Q41: 118.1 | S41: 117.8 | T41: 115 | V41: 114.2 | X41: 110.9 | Z41: 113.7 | AB41: 110.7 | AC41: =AB41 -> 110.7 | AE41: 110.4 | AG41: 111.3 | AI41: 109 | AJ41: 109.7 | AL41: 108.9 | AN41: 111.4 | AP41: 107.7 | AR41: 109.8 | AT41: 113.3
A42: Rural+Urban | B42: 2013 | C42: December | D42: 119.1 | F42: 116.7 | H42: 123.5 | I42: 113.4 | J42: 107.3 | K42: 113.3 | L42: 145.4 | M42: 108.7 | N42: 101.5 | O42: 110.5 | P42: 112.1 | Q42: 117.4 | S42: 118.4 | T42: 114 | V42: 115.2 | X42: 112.7 | Z42: 114.8 | AB42: 110.7 | AC42: =AB42 -> 110.7 | AE42: 111.9 | AG42: 111.7 | AI42: 109.7 | AJ42: 109.8 | AL42: 109 | AN42: 111.5 | AP42: 107.9 | AR42: 110 | AT42: 114.5
...

Sheet Cleaned Data
A1: Sector | B1: Year | C1: Month | D1: Cereals and products | E1: Meat and fish | F1: Egg | G1: Milk and products | H1: Oils and fats | I1: Fruits | J1: Vegetables | K1: Pulses and products | L1: Sugar and Confectionery | M1: Spices | N1: Non-alcoholic beverages | O1: Prepared meals, snacks, sweets etc. | P1: Food and beverages | Q1: Pan, tobacco and intoxicants | R1: Clothing | S1: Footwear | T1: Clothing and footwear | U1: Housing | V1: Fuel and light | W1: Household goods and services | X1: Health | Y1: Transport and communication | Z1: Recreation and amusement | AA1: Education | AB1: Personal care and effects | AC1: Miscellaneous | AD1: General index
A2: Rural | B2: 2013 | C2: January | D2: 107.5 | E2: 106.3 | F2: 108.1 | G2: 104.9 | H2: 106.1 | I2: 103.9 | J2: 101.9 | K2: 106.1 | L2: 106.8 | M2: 103.1 | N2: 104.8 | O2: 106.7 | P2: 105.5 | Q2: 105.1 | R2: 106.5 | S2: 105.8 | T2: 106.4 | U2: =U3 -> 100.3 | V2: 105.5 | W2: 104.8 | X2: 104 | Y2: 103.3 | Z2: 103.4 | AA2: 103.8 | AB2: 104.7 | AC2: 104 | AD2: 105.1
A3: Urban | B3: 2013 | C3: January | D3: 110.5 | E3: 109.1 | F3: 113 | G3: 103.6 | H3: 103.4 | I3: 102.3 | J3: 102.9 | K3: 105.8 | L3: 105.1 | M3: 101.8 | N3: 105.1 | O3: 107.9 | P3: 105.9 | Q3: 105.2 | R3: 105.9 | S3: 105 | T3: 105.8 | U3: 100.3 | V3: 105.4 | W3: 104.8 | X3: 104.1 | Y3: 103.2 | Z3: 102.9 | AA3: 103.5 | AB3: 104.3 | AC3: 103.7 | AD3: 104
A4: Rural+Urban | B4: 2013 | C4: January | D4: 108.4 | E4: 107.3 | F4: 110 | G4: 104.4 | H4: 105.1 | I4: 103.2 | J4: 102.2 | K4: 106 | L4: 106.2 | M4: 102.7 | N4: 104.9 | O4: 107.3 | P4: 105.6 | Q4: 105.1 | R4: 106.3 | S4: 105.5 | T4: 106.2 | U4: 100.3 | V4: 105.5 | W4: 104.8 | X4: 104 | Y4: 103.2 | Z4: 103.1 | AA4: 103.6 | AB4: 104.5 | AC4: 103.9 | AD4: 104.6
A5: Rural | B5: 2013 | C5: February | D5: 109.2 | E5: 108.7 | F5: 110.2 | G5: 105.4 | H5: 106.7 | I5: 104 | J5: 102.4 | K5: 105.9 | L5: 105.7 | M5: 103.1 | N5: 105.1 | O5: 107.7 | P5: 106.3 | Q5: 105.6 | R5: 107.1 | S5: 106.3 | T5: 107 | U5: =U6 -> 100.4 | V5: 106.2 | W5: 105.2 | X5: 104.4 | Y5: 103.9 | Z5: 104 | AA5: 104.1 | AB5: 104.6 | AC5: 104.4 | AD5: 105.8
A6: Urban | B6: 2013 | C6: February | D6: 112.9 | E6: 112.9 | F6: 116.9 | G6: 104 | H6: 103.5 | I6: 103.1 | J6: 104.9 | K6: 104.1 | L6: 103.8 | M6: 102.3 | N6: 106 | O6: 109 | P6: 107.2 | Q6: 106 | R6: 106.6 | S6: 105.5 | T6: 106.4 | U6: 100.4 | V6: 105.7 | W6: 105.2 | X6: 104.7 | Y6: 104.4 | Z6: 103.3 | AA6: 103.7 | AB6: 104.3 | AC6: 104.3 | AD6: 104.7
A7: Rural+Urban | B7: 2013 | C7: February | D7: 110.4 | E7: 110.2 | F7: 112.8 | G7: 104.9 | H7: 105.5 | I7: 103.6 | J7: 103.2 | K7: 105.3 | L7: 105.1 | M7: 102.8 | N7: 105.5 | O7: 108.3 | P7: 106.6 | Q7: 105.7 | R7: 106.9 | S7: 106 | T7: 106.8 | U7: 100.4 | V7: 106 | W7: 105.2 | X7: 104.5 | Y7: 104.2 | Z7: 103.6 | AA7: 103.9 | AB7: 104.5 | AC7: 104.4 | AD7: 105.3
A8: Rural | B8: 2013 | C8: March | D8: 110.2 | E8: 108.8 | F8: 109.9 | G8: 105.6 | H8: 106.2 | I8: 105.7 | J8: 101.4 | K8: 105.7 | L8: 105 | M8: 103.3 | N8: 105.6 | O8: 108.2 | P8: 106.6 | Q8: 106.5 | R8: 107.6 | S8: 106.8 | T8: 107.5 | U8: =U9 -> 100.4 | V8: 106.1 | W8: 105.6 | X8: 104.7 | Y8: 104.6 | Z8: 104 | AA8: 104.3 | AB8: 104.3 | AC8: 104.6 | AD8: 106
A9: Urban | B9: 2013 | C9: March | D9: 113.9 | E9: 111.4 | F9: 113.2 | G9: 104.3 | H9: 102.7 | I9: 104.9 | J9: 103.8 | K9: 103.5 | L9: 102.6 | M9: 102.4 | N9: 107 | O9: 109.8 | P9: 107.3 | Q9: 106.8 | R9: 107.2 | S9: 106 | T9: 107 | U9: 100.4 | V9: 106 | W9: 105.7 | X9: 105.2 | Y9: 105.5 | Z9: 103.5 | AA9: 103.8 | AB9: 104.2 | AC9: 104.9 | AD9: 105
A10: Rural+Urban | B10: 2013 | C10: March | D10: 111.4 | E10: 109.7 | F10: 111.2 | G10: 105.1 | H10: 104.9 | I10: 105.3 | J10: 102.2 | K10: 105 | L10: 104.2 | M10: 103 | N10: 106.2 | O10: 108.9 | P10: 106.9 | Q10: 106.6 | R10: 107.4 | S10: 106.5 | T10: 107.3 | U10: 100.4 | V10: 106.1 | W10: 105.6 | X10: 104.9 | Y10: 105.1 | Z10: 103.7 | AA10: 104 | AB10: 104.3 | AC10: 104.7 | AD10: 105.5
A11: Rural | B11: 2013 | C11: April | D11: 110.2 | E11: 109.5 | F11: 106.9 | G11: 106.3 | H11: 105.7 | I11: 108.3 | J11: 103.4 | K11: 105.7 | L11: 104.2 | M11: 103.2 | N11: 106.5 | O11: 108.8 | P11: 107.1 | Q11: 107.1 | R11: 108.1 | S11: 107.4 | T11: 108 | U11: =U12 -> 100.5 | V11: 106.5 | W11: 106.1 | X11: 105.1 | Y11: 104.4 | Z11: 104.5 | AA11: 104.8 | AB11: 102.7 | AC11: 104.6 | AD11: 106.4
A12: Urban | B12: 2013 | C12: April | D12: 114.6 | E12: 113.4 | F12: 106 | G12: 104.7 | H12: 102.1 | I12: 109.5 | J12: 109.7 | K12: 104.6 | L12: 102 | M12: 103.5 | N12: 108.2 | O12: 110.6 | P12: 108.8 | Q12: 108.5 | R12: 107.9 | S12: 106.4 | T12: 107.7 | U12: 100.5 | V12: 106.4 | W12: 106.5 | X12: 105.7 | Y12: 105 | Z12: 104 | AA12: 105.2 | AB12: 103.2 | AC12: 105.1 | AD12: 105.7
A13: Rural+Urban | B13: 2013 | C13: April | D13: 111.6 | E13: 110.9 | F13: 106.6 | G13: 105.7 | H13: 104.4 | I13: 108.9 | J13: 105.5 | K13: 105.3 | L13: 103.5 | M13: 103.3 | N13: 107.2 | O13: 109.6 | P13: 107.7 | Q13: 107.5 | R13: 108 | S13: 107 | T13: 107.9 | U13: 100.5 | V13: 106.5 | W13: 106.3 | X13: 105.3 | Y13: 104.7 | Z13: 104.2 | AA13: 105 | AB13: 102.9 | AC13: 104.8 | AD13: 106.1
A14: Rural | B14: 2013 | C14: May | D14: 110.9 | E14: 109.8 | F14: 105.9 | G14: 107.5 | H14: 105.3 | I14: 108.1 | J14: 107.3 | K14: 106.1 | L14: 103.7 | M14: 104 | N14: 107.4 | O14: 109.9 | P14: 108.1 | Q14: 108.1 | R14: 108.8 | S14: 107.9 | T14: 108.6 | U14: =U15 -> 100.5 | V14: 107.5 | W14: 106.8 | X14: 105.7 | Y14: 104.1 | Z14: 105 | AA14: 105.5 | AB14: 102.1 | AC14: 104.8 | AD14: 107.2
A15: Urban | B15: 2013 | C15: May | D15: 115.4 | E15: 114.2 | F15: 102.7 | G15: 105.5 | H15: 101.5 | I15: 110.6 | J15: 123.7 | K15: 105.2 | L15: 101.9 | M15: 105 | N15: 109.1 | O15: 111.3 | P15: 111.1 | Q15: 109.8 | R15: 108.5 | S15: 106.7 | T15: 108.3 | U15: 100.5 | V15: 107.2 | W15: 107.1 | X15: 106.2 | Y15: 103.9 | Z15: 104.6 | AA15: 105.7 | AB15: 102.6 | AC15: 104.9 | AD15: 106.6
A16: Rural+Urban | B16: 2013 | C16: May | D16: 112.3 | E16: 111.3 | F16: 104.7 | G16: 106.8 | H16: 103.9 | I16: 109.3 | J16: 112.9 | K16: 105.8 | L16: 103.1 | M16: 104.3 | N16: 108.1 | O16: 110.5 | P16: 109.2 | Q16: 108.6 | R16: 108.7 | S16: 107.4 | T16: 108.5 | U16: 100.5 | V16: 107.4 | W16: 106.9 | X16: 105.9 | Y16: 104 | Z16: 104.8 | AA16: 105.6 | AB16: 102.3 | AC16: 104.8 | AD16: 106.9
A17: Rural | B17: 2013 | C17: June | D17: 112.3 | E17: 112.1 | F17: 108.1 | G17: 108.3 | H17: 105.9 | I17: 109.2 | J17: 118 | K17: 106.8 | L17: 104.1 | M17: 105.4 | N17: 108.2 | O17: 111 | P17: 110.6 | Q17: 109 | R17: 109.7 | S17: 108.8 | T17: 109.5 | U17: =U18 -> 106.6 | V17: 108.5 | W17: 107.5 | X17: 106.3 | Y17: 105 | Z17: 105.6 | AA17: 106.5 | AB17: 102.5 | AC17: 105.5 | AD17: 108.9
A18: Urban | B18: 2013 | C18: June | D18: 117 | E18: 120.1 | F18: 112.5 | G18: 107.3 | H18: 101.3 | I18: 112.4 | J18: 143.6 | K18: 105.4 | L18: 101.4 | M18: 106.4 | N18: 110 | O18: 112.2 | P18: 115 | Q18: 110.9 | R18: 109.2 | S18: 107.2 | T18: 108.9 | U18: 106.6 | V18: 108 | W18: 107.7 | X18: 106.5 | Y18: 105.2 | Z18: 105.2 | AA18: 108.1 | AB18: 103.3 | AC18: 106.1 | AD18: 109.7
A19: Rural+Urban | B19: 2013 | C19: June | D19: 113.8 | E19: 114.9 | F19: 109.8 | G19: 107.9 | H19: 104.2 | I19: 110.7 | J19: 126.7 | K19: 106.3 | L19: 103.2 | M19: 105.7 | N19: 109 | O19: 111.6 | P19: 112.2 | Q19: 109.5 | R19: 109.5 | S19: 108.1 | T19: 109.3 | U19: 106.6 | V19: 108.3 | W19: 107.6 | X19: 106.4 | Y19: 105.1 | Z19: 105.4 | AA19: 107.4 | AB19: 102.8 | AC19: 105.8 | AD19: 109.3
A20: Rural | B20: 2013 | C20: July | D20: 113.4 | E20: 114.9 | F20: 110.5 | G20: 109.3 | H20: 106.2 | I20: 110.3 | J20: 129.2 | K20: 107.1 | L20: 104.3 | M20: 106.4 | N20: 109.1 | O20: 112.1 | P20: 113.1 | Q20: 109.8 | R20: 110.5 | S20: 109.5 | T20: 110.3 | U20: =U21 -> 107.7 | V20: 109.5 | W20: 108.3 | X20: 106.9 | Y20: 106.8 | Z20: 106.4 | AA20: 107.8 | AB20: 102.5 | AC20: 106.5 | AD20: 110.7
A21: Urban | B21: 2013 | C21: July | D21: 117.8 | E21: 119.2 | F21: 114 | G21: 108.3 | H21: 101.1 | I21: 113.2 | J21: 160.9 | K21: 105.1 | L21: 101.3 | M21: 107.5 | N21: 110.4 | O21: 113.1 | P21: 117.5 | Q21: 111.7 | R21: 109.8 | S21: 107.8 | T21: 109.5 | U21: 107.7 | V21: 108.6 | W21: 108.1 | X21: 107.1 | Y21: 107.3 | Z21: 105.9 | AA21: 110.1 | AB21: 103.2 | AC21: 107.3 | AD21: 111.4
A22: Rural+Urban | B22: 2013 | C22: July | D22: 114.8 | E22: 116.4 | F22: 111.9 | G22: 108.9 | H22: 104.3 | I22: 111.7 | J22: 140 | K22: 106.4 | L22: 103.3 | M22: 106.8 | N22: 109.6 | O22: 112.6 | P22: 114.7 | Q22: 110.3 | R22: 110.2 | S22: 108.8 | T22: 110 | U22: 107.7 | V22: 109.2 | W22: 108.2 | X22: 107 | Y22: 107.1 | Z22: 106.1 | AA22: 109.1 | AB22: 102.8 | AC22: 106.9 | AD22: 111
A23: Rural | B23: 2013 | C23: August | D23: 114.3 | E23: 115.4 | F23: 111.1 | G23: 110 | H23: 106.4 | I23: 110.8 | J23: 138.9 | K23: 107.4 | L23: 104.1 | M23: 106.9 | N23: 109.7 | O23: 112.6 | P23: 114.9 | Q23: 110.7 | R23: 111.3 | S23: 110.2 | T23: 111.1 | U23: =U24 -> 108.9 | V23: 109.9 | W23: 108.7 | X23: 107.5 | Y23: 107.8 | Z23: 106.8 | AA23: 108.7 | AB23: 105 | AC23: 107.5 | AD23: 112.1
A24: Urban | B24: 2013 | C24: August | D24: 118.3 | E24: 120.4 | F24: 112.7 | G24: 108.9 | H24: 101.1 | I24: 108.7 | J24: 177 | K24: 104.7 | L24: 101 | M24: 108.5 | N24: 110.9 | O24: 114.3 | P24: 119.6 | Q24: 112.4 | R24: 110.6 | S24: 108.3 | T24: 110.2 | U24: 108.9 | V24: 109.3 | W24: 108.7 | X24: 107.6 | Y24: 108.1 | Z24: 106.5 | AA24: 110.8 | AB24: 106 | AC24: 108.3 | AD24: 112.7
A25: Rural+Urban | B25: 2013 | C25: August | D25: 115.6 | E25: 117.2 | F25: 111.7 | G25: 109.6 | H25: 104.5 | I25: 109.8 | J25: 151.8 | K25: 106.5 | L25: 103.1 | M25: 107.4 | N25: 110.2 | O25: 113.4 | P25: 116.6 | Q25: 111.2 | R25: 111 | S25: 109.4 | T25: 110.7 | U25: 108.9 | V25: 109.7 | W25: 108.7 | X25: 107.5 | Y25: 108 | Z25: 106.6 | AA25: 109.9 | AB25: 105.4 | AC25: 107.9 | AD25: 112.4
A26: Rural | B26: 2013 | C26: September | D26: 115.4 | E26: 115.7 | F26: 111.7 | G26: 111 | H26: 107.4 | I26: 110.9 | J26: 154 | K26: 108.1 | L26: 104.2 | M26: 107.9 | N26: 110.4 | O26: 114 | P26: 117.8 | Q26: 111.7 | R26: 112.7 | S26: 111.4 | T26: 112.5 | U26: =U27 -> 109.7 | V26: 111.1 | W26: 109.6 | X26: 108.3 | Y26: 109.3 | Z26: 107.7 | AA26: 109.8 | AB26: 106.7 | AC26: 108.7 | AD26: 114.2
A27: Urban | B27: 2013 | C27: September | D27: 118.6 | E27: 119.1 | F27: 113.2 | G27: 109.6 | H27: 101.7 | I27: 103.2 | J27: 174.3 | K27: 105.1 | L27: 100.8 | M27: 109.1 | N27: 111.1 | O27: 115.4 | P27: 119.2 | Q27: 112.9 | R27: 111.4 | S27: 109 | T27: 111.1 | U27: 109.7 | V27: 109.5 | W27: 109.6 | X27: 107.9 | Y27: 110.4 | Z27: 107.4 | AA27: 111.2 | AB27: 106.9 | AC27: 109.4 | AD27: 113.2
A28: Rural+Urban | B28: 2013 | C28: September | D28: 116.4 | E28: 116.9 | F28: 112.3 | G28: 110.5 | H28: 105.3 | I28: 107.3 | J28: 160.9 | K28: 107.1 | L28: 103.1 | M28: 108.3 | N28: 110.7 | O28: 114.6 | P28: 118.3 | Q28: 112 | R28: 112.2 | S28: 110.4 | T28: 111.9 | U28: 109.7 | V28: 110.5 | W28: 109.6 | X28: 108.1 | Y28: 109.9 | Z28: 107.5 | AA28: 110.6 | AB28: 106.8 | AC28: 109 | AD28: 113.7
A29: Rural | B29: 2013 | C29: October | D29: 116.3 | E29: 115.4 | F29: 112.6 | G29: 111.7 | H29: 107.7 | I29: 113.2 | J29: 164.9 | K29: 108.3 | L29: 103.9 | M29: 108.2 | N29: 111.1 | O29: 114.9 | P29: 119.8 | Q29: 112.2 | R29: 113.6 | S29: 112.3 | T29: 113.4 | U29: =U30 -> 110.5 | V29: 111.6 | W29: 110.4 | X29: 108.9 | Y29: 109.3 | Z29: 108.3 | AA29: 110.2 | AB29: 107.5 | AC29: 109.1 | AD29: 115.5
A30: Urban | B30: 2013 | C30: October | D30: 118.9 | E30: 118.1 | F30: 114.5 | G30: 110.4 | H30: 102.3 | I30: 106.2 | J30: 183.5 | K30: 105.3 | L30: 100.2 | M30: 109.6 | N30: 111.4 | O30: 116 | P30: 120.8 | Q30: 113.5 | R30: 112.5 | S30: 109.7 | T30: 112 | U30: 110.5 | V30: 109.7 | W30: 110.2 | X30: 108.2 | Y30: 109.7 | Z30: 108 | AA30: 111.3 | AB30: 107.3 | AC30: 109.4 | AD30: 114
A31: Rural+Urban | B31: 2013 | C31: October | D31: 117.1 | E31: 116.3 | F31: 113.3 | G31: 111.2 | H31: 105.7 | I31: 109.9 | J31: 171.2 | K31: 107.3 | L31: 102.7 | M31: 108.7 | N31: 111.2 | O31: 115.4 | P31: 120.2 | Q31: 112.5 | R31: 113.2 | S31: 111.2 | T31: 112.8 | U31: 110.5 | V31: 110.9 | W31: 110.3 | X31: 108.6 | Y31: 109.5 | Z31: 108.1 | AA31: 110.8 | AB31: 107.4 | AC31: 109.2 | AD31: 114.8
A32: Rural | B32: 2013 | C32: November | D32: 117.3 | E32: 114.9 | F32: 116.2 | G32: 112.8 | H32: 108.9 | I32: 116.6 | J32: 178.1 | K32: 109.1 | L32: 103.6 | M32: 109 | N32: 111.8 | O32: 116 | P32: 122.5 | Q32: 112.8 | R32: 114.6 | S32: 113.1 | T32: 114.4 | U32: =U33 -> 111.1 | V32: 112.6 | W32: 111.3 | X32: 109.7 | Y32: 109.6 | Z32: 108.7 | AA32: 111 | AB32: 108.2 | AC32: 109.8 | AD32: 117.4
A33: Urban | B33: 2013 | C33: November | D33: 119.8 | E33: 116.3 | F33: 122.6 | G33: 112 | H33: 103.2 | I33: 110 | J33: 192.8 | K33: 106.3 | L33: 99.5 | M33: 110.3 | N33: 111.8 | O33: 117.1 | P33: 122.9 | Q33: 114.1 | R33: 113.5 | S33: 110.3 | T33: 113 | U33: 111.1 | V33: 110 | W33: 110.9 | X33: 108.6 | Y33: 109.5 | Z33: 108.5 | AA33: 111.3 | AB33: 107.9 | AC33: 109.6 | AD33: 115
A34: Rural+Urban | B34: 2013 | C34: November | D34: 118.1 | E34: 115.4 | F34: 118.7 | G34: 112.5 | H34: 106.8 | I34: 113.5 | J34: 183.1 | K34: 108.2 | L34: 102.2 | M34: 109.4 | N34: 111.8 | O34: 116.5 | P34: 122.6 | Q34: 113.1 | R34: 114.2 | S34: 111.9 | T34: 113.8 | U34: 111.1 | V34: 111.6 | W34: 111.1 | X34: 109.3 | Y34: 109.5 | Z34: 108.6 | AA34: 111.2 | AB34: 108.1 | AC34: 109.7 | AD34: 116.3
A35: Rural | B35: 2013 | C35: December | D35: 118.4 | E35: 115.9 | F35: 120.4 | G35: 113.8 | H35: 109.5 | I35: 115.5 | J35: 145.7 | K35: 109.5 | L35: 102.9 | M35: 109.8 | N35: 112.1 | O35: 116.8 | P35: 118.7 | Q35: 113.6 | R35: 115.8 | S35: 114 | T35: 115.5 | U35: =U36 -> 110.7 | V35: 112.8 | W35: 112.1 | X35: 110.1 | Y35: 109.9 | Z35: 109.2 | AA35: 111.6 | AB35: 108.1 | AC35: 110.1 | AD35: 115.5
A36: Urban | B36: 2013 | C36: December | D36: 120.5 | E36: 118.1 | F36: 128.5 | G36: 112.8 | H36: 103.4 | I36: 110.7 | J36: 144.8 | K36: 107.1 | L36: 98.6 | M36: 111.9 | N36: 112.1 | O36: 118.1 | P36: 117.8 | Q36: 115 | R36: 114.2 | S36: 110.9 | T36: 113.7 | U36: 110.7 | V36: 110.4 | W36: 111.3 | X36: 109 | Y36: 109.7 | Z36: 108.9 | AA36: 111.4 | AB36: 107.7 | AC36: 109.8 | AD36: 113.3
A37: Rural+Urban | B37: 2013 | C37: December | D37: 119.1 | E37: 116.7 | F37: 123.5 | G37: 113.4 | H37: 107.3 | I37: 113.3 | J37: 145.4 | K37: 108.7 | L37: 101.5 | M37: 110.5 | N37: 112.1 | O37: 117.4 | P37: 118.4 | Q37: 114 | R37: 115.2 | S37: 112.7 | T37: 114.8 | U37: 110.7 | V37: 111.9 | W37: 111.7 | X37: 109.7 | Y37: 109.8 | Z37: 109 | AA37: 111.5 | AB37: 107.9 | AC37: 110 | AD37: 114.5
A38: Rural | B38: 2014 | C38: January | D38: 118.9 | E38: 117.1 | F38: 120.5 | G38: 114.4 | H38: 109 | I38: 115.5 | J38: 123.9 | K38: 109.6 | L38: 101.8 | M38: 110.2 | N38: 112.4 | O38: 117.3 | P38: 116 | Q38: 114 | R38: 116.5 | S38: 114.5 | T38: 116.2 | U38: =U39 -> 111.6 | V38: 113 | W38: 112.6 | X38: 110.6 | Y38: 110.5 | Z38: 109.6 | AA38: 111.8 | AB38: 108.3 | AC38: 110.6 | AD38: 114.2
A39: Urban | B39: 2014 | C39: January | D39: 121.2 | E39: 122 | F39: 129.9 | G39: 113.6 | H39: 102.9 | I39: 112.1 | J39: 118.9 | K39: 107.5 | L39: 96.9 | M39: 112.7 | N39: 112.1 | O39: 119 | P39: 115.5 | Q39: 115.7 | R39: 114.8 | S39: 111.3 | T39: 114.3 | U39: 111.6 | V39: 111 | W39: 111.9 | X39: 109.7 | Y39: 110.8 | Z39: 109.8 | AA39: 111.5 | AB39: 108 | AC39: 110.5 | AD39: 112.9
A40: Rural+Urban | B40: 2014 | C40: January | D40: 119.6 | E40: 118.8 | F40: 124.1 | G40: 114.1 | H40: 106.8 | I40: 113.9 | J40: 122.2 | K40: 108.9 | L40: 100.2 | M40: 111 | N40: 112.3 | O40: 118.1 | P40: 115.8 | Q40: 114.5 | R40: 115.8 | S40: 113.2 | T40: 115.4 | U40: 111.6 | V40: 112.2 | W40: 112.3 | X40: 110.3 | Y40: 110.7 | Z40: 109.7 | AA40: 111.6 | AB40: 108.2 | AC40: 110.6 | AD40: 113.6
...

Sheet PS1
A1: Sector | B1: Year | C1: Month | D1: Cereals and products | E1: Meat and fish | F1: Egg | G1: Milk and products | H1: Oils and fats | I1: Fruits | J1: Vegetables | K1: Pulses and products | L1: Sugar and Confectionery | M1: Spices | N1: Non-alcoholic beverages | O1: Prepared meals, snacks, sweets etc. | P1: Food and beverages | Q1: Pan, tobacco and intoxicants | R1: Clothing | S1: Footwear | T1: Clothing and footwear | U1: Household goods and services | V1: Health | W1: Transport and communication | X1: Recreation and amusement | Y1: Education | Z1: Personal care and effects | AA1: Miscellaneous | AB1: General index | AC1: Food | AD1: Clothing & Footwear | AE1: Housing | AF1: Fuel and light | AG1: Miscellneaous | AH1: Total CPI | AI1: Food % | AJ1: C &F % | AK1: Housing % | AL1: Fuel & Light% | AM1: Miscellneous %
A2: Rural | B2: 2013 | C2: January | D2: 107.5 | E2: 106.3 | F2: 108.1 | G2: 104.9 | H2: 106.1 | I2: 103.9 | J2: 101.9 | K2: 106.1 | L2: 106.8 | M2: 103.1 | N2: 104.8 | O2: 106.7 | P2: 105.5 | Q2: 105.1 | R2: 106.5 | S2: 105.8 | T2: 106.4 | U2: 104.8 | V2: 104 | W2: 103.3 | X2: 103.4 | Y2: 103.8 | Z2: 104.7 | AA2: 104 | AB2: 105.1 | AC2: =AVERAGE(D2:Q2) -> 105.48571 | AD2: =AVERAGE(R2:T2) -> 106.23333 | AE2: 100.3 | AF2: 105.5 | AG2: =AVERAGE(U2:Z2) -> 104 | AH2: =SUM(AC2:AG2) -> 521.51905 | AI2: =AC2/$AH$2*100 -> 20.226627 | AJ2: =AD2/$AH$2*100 -> 20.369981 | AK2: =AE2/$AH$2*100 -> 19.232279 | AL2: =AF2/$AH$2*100 -> 20.229367 | AM2: =AG2/$AH$2*100 -> 19.941745
A3: Urban | B3: 2013 | C3: January | D3: 110.5 | E3: 109.1 | F3: 113 | G3: 103.6 | H3: 103.4 | I3: 102.3 | J3: 102.9 | K3: 105.8 | L3: 105.1 | M3: 101.8 | N3: 105.1 | O3: 107.9 | P3: 105.9 | Q3: 105.2 | R3: 105.9 | S3: 105 | T3: 105.8 | U3: 104.8 | V3: 104.1 | W3: 103.2 | X3: 102.9 | Y3: 103.5 | Z3: 104.3 | AA3: 103.7 | AB3: 104 | AC3: =AVERAGE(D3:Q3) -> 105.82857 | AD3: =AVERAGE(R3:T3) -> 105.56667 | AE3: 100.3 | AF3: 105.4 | AG3: =AVERAGE(U3:Z3) -> 103.8 | AH3: =SUM(AC3:AG3) -> 520.89524 | AI3: =AC3/$AH$2*100 -> 20.292369 | AJ3: =AD3/$AH$2*100 -> 20.24215 | AK3: =AE3/$AH$2*100 -> 19.232279 | AL3: =AF3/$AH$2*100 -> 20.210192 | AM3: =AG3/$AH$2*100 -> 19.903396
A4: Rural+Urban | B4: 2013 | C4: January | D4: 108.4 | E4: 107.3 | F4: 110 | G4: 104.4 | H4: 105.1 | I4: 103.2 | J4: 102.2 | K4: 106 | L4: 106.2 | M4: 102.7 | N4: 104.9 | O4: 107.3 | P4: 105.6 | Q4: 105.1 | R4: 106.3 | S4: 105.5 | T4: 106.2 | U4: 104.8 | V4: 104 | W4: 103.2 | X4: 103.1 | Y4: 103.6 | Z4: 104.5 | AA4: 103.9 | AB4: 104.6 | AC4: =AVERAGE(D4:Q4) -> 105.6 | AD4: =AVERAGE(R4:T4) -> 106 | AE4: 100.3 | AF4: 105.5 | AG4: =AVERAGE(U4:Z4) -> 103.86667 | AH4: =SUM(AC4:AG4) -> 521.26667 | AI4: =AC4/$AH$2*100 -> 20.248541 | AJ4: =AD4/$AH$2*100 -> 20.32524 | AK4: =AE4/$AH$2*100 -> 19.232279 | AL4: =AF4/$AH$2*100 -> 20.229367 | AM4: =AG4/$AH$2*100 -> 19.916179
A5: Rural | B5: 2013 | C5: February | D5: 109.2 | E5: 108.7 | F5: 110.2 | G5: 105.4 | H5: 106.7 | I5: 104 | J5: 102.4 | K5: 105.9 | L5: 105.7 | M5: 103.1 | N5: 105.1 | O5: 107.7 | P5: 106.3 | Q5: 105.6 | R5: 107.1 | S5: 106.3 | T5: 107 | U5: 105.2 | V5: 104.4 | W5: 103.9 | X5: 104 | Y5: 104.1 | Z5: 104.6 | AA5: 104.4 | AB5: 105.8 | AC5: =AVERAGE(D5:Q5) -> 106.14286 | AD5: =AVERAGE(R5:T5) -> 106.8 | AE5: 100.4 | AF5: 106.2 | AG5: =AVERAGE(U5:Z5) -> 104.36667 | AH5: =SUM(AC5:AG5) -> 523.90952 | AI5: =AC5/$AH$2*100 -> 20.352633 | AJ5: =AD5/$AH$2*100 -> 20.478638 | AK5: =AE5/$AH$2*100 -> 19.251454 | AL5: =AF5/$AH$2*100 -> 20.36359 | AM5: =AG5/$AH$2*100 -> 20.012053
A6: Urban | B6: 2013 | C6: February | D6: 112.9 | E6: 112.9 | F6: 116.9 | G6: 104 | H6: 103.5 | I6: 103.1 | J6: 104.9 | K6: 104.1 | L6: 103.8 | M6: 102.3 | N6: 106 | O6: 109 | P6: 107.2 | Q6: 106 | R6: 106.6 | S6: 105.5 | T6: 106.4 | U6: 105.2 | V6: 104.7 | W6: 104.4 | X6: 103.3 | Y6: 103.7 | Z6: 104.3 | AA6: 104.3 | AB6: 104.7 | AC6: =AVERAGE(D6:Q6) -> 106.9 | AD6: =AVERAGE(R6:T6) -> 106.16667 | AE6: 100.4 | AF6: 105.7 | AG6: =AVERAGE(U6:Z6) -> 104.26667 | AH6: =SUM(AC6:AG6) -> 523.43333 | AI6: =AC6/$AH$2*100 -> 20.497813 | AJ6: =AD6/$AH$2*100 -> 20.357198 | AK6: =AE6/$AH$2*100 -> 19.251454 | AL6: =AF6/$AH$2*100 -> 20.267716 | AM6: =AG6/$AH$2*100 -> 19.992878
A7: Rural+Urban | B7: 2013 | C7: February | D7: 110.4 | E7: 110.2 | F7: 112.8 | G7: 104.9 | H7: 105.5 | I7: 103.6 | J7: 103.2 | K7: 105.3 | L7: 105.1 | M7: 102.8 | N7: 105.5 | O7: 108.3 | P7: 106.6 | Q7: 105.7 | R7: 106.9 | S7: 106 | T7: 106.8 | U7: 105.2 | V7: 104.5 | W7: 104.2 | X7: 103.6 | Y7: 103.9 | Z7: 104.5 | AA7: 104.4 | AB7: 105.3 | AC7: =AVERAGE(D7:Q7) -> 106.42143 | AD7: =AVERAGE(R7:T7) -> 106.56667 | AE7: 100.4 | AF7: 106 | AG7: =AVERAGE(U7:Z7) -> 104.31667 | AH7: =SUM(AC7:AG7) -> 523.70476 | AI7: =AC7/$AH$2*100 -> 20.406048 | AJ7: =AD7/$AH$2*100 -> 20.433897 | AK7: =AE7/$AH$2*100 -> 19.251454 | AL7: =AF7/$AH$2*100 -> 20.32524 | AM7: =AG7/$AH$2*100 -> 20.002465
A8: Rural | B8: 2013 | C8: March | D8: 110.2 | E8: 108.8 | F8: 109.9 | G8: 105.6 | H8: 106.2 | I8: 105.7 | J8: 101.4 | K8: 105.7 | L8: 105 | M8: 103.3 | N8: 105.6 | O8: 108.2 | P8: 106.6 | Q8: 106.5 | R8: 107.6 | S8: 106.8 | T8: 107.5 | U8: 105.6 | V8: 104.7 | W8: 104.6 | X8: 104 | Y8: 104.3 | Z8: 104.3 | AA8: 104.6 | AB8: 106 | AC8: =AVERAGE(D8:Q8) -> 106.33571 | AD8: =AVERAGE(R8:T8) -> 107.3 | AE8: 100.4 | AF8: 106.1 | AG8: =AVERAGE(U8:Z8) -> 104.58333 | AH8: =SUM(AC8:AG8) -> 524.71905 | AI8: =AC8/$AH$2*100 -> 20.389613 | AJ8: =AD8/$AH$2*100 -> 20.574512 | AK8: =AE8/$AH$2*100 -> 19.251454 | AL8: =AF8/$AH$2*100 -> 20.344415 | AM8: =AG8/$AH$2*100 -> 20.053598
A9: Urban | B9: 2013 | C9: March | D9: 113.9 | E9: 111.4 | F9: 113.2 | G9: 104.3 | H9: 102.7 | I9: 104.9 | J9: 103.8 | K9: 103.5 | L9: 102.6 | M9: 102.4 | N9: 107 | O9: 109.8 | P9: 107.3 | Q9: 106.8 | R9: 107.2 | S9: 106 | T9: 107 | U9: 105.7 | V9: 105.2 | W9: 105.5 | X9: 103.5 | Y9: 103.8 | Z9: 104.2 | AA9: 104.9 | AB9: 105 | AC9: =AVERAGE(D9:Q9) -> 106.68571 | AD9: =AVERAGE(R9:T9) -> 106.73333 | AE9: 100.4 | AF9: 106 | AG9: =AVERAGE(U9:Z9) -> 104.65 | AH9: =SUM(AC9:AG9) -> 524.46905 | AI9: =AC9/$AH$2*100 -> 20.456724 | AJ9: =AD9/$AH$2*100 -> 20.465855 | AK9: =AE9/$AH$2*100 -> 19.251454 | AL9: =AF9/$AH$2*100 -> 20.32524 | AM9: =AG9/$AH$2*100 -> 20.066381
A10: Rural+Urban | B10: 2013 | C10: March | D10: 111.4 | E10: 109.7 | F10: 111.2 | G10: 105.1 | H10: 104.9 | I10: 105.3 | J10: 102.2 | K10: 105 | L10: 104.2 | M10: 103 | N10: 106.2 | O10: 108.9 | P10: 106.9 | Q10: 106.6 | R10: 107.4 | S10: 106.5 | T10: 107.3 | U10: 105.6 | V10: 104.9 | W10: 105.1 | X10: 103.7 | Y10: 104 | Z10: 104.3 | AA10: 104.7 | AB10: 105.5 | AC10: =AVERAGE(D10:Q10) -> 106.47143 | AD10: =AVERAGE(R10:T10) -> 107.06667 | AE10: 100.4 | AF10: 106.1 | AG10: =AVERAGE(U10:Z10) -> 104.6 | AH10: =SUM(AC10:AG10) -> 524.6381 | AI10: =AC10/$AH$2*100 -> 20.415636 | AJ10: =AD10/$AH$2*100 -> 20.529771 | AK10: =AE10/$AH$2*100 -> 19.251454 | AL10: =AF10/$AH$2*100 -> 20.344415 | AM10: =AG10/$AH$2*100 -> 20.056794
A11: Rural | B11: 2013 | C11: April | D11: 110.2 | E11: 109.5 | F11: 106.9 | G11: 106.3 | H11: 105.7 | I11: 108.3 | J11: 103.4 | K11: 105.7 | L11: 104.2 | M11: 103.2 | N11: 106.5 | O11: 108.8 | P11: 107.1 | Q11: 107.1 | R11: 108.1 | S11: 107.4 | T11: 108 | U11: 106.1 | V11: 105.1 | W11: 104.4 | X11: 104.5 | Y11: 104.8 | Z11: 102.7 | AA11: 104.6 | AB11: 106.4 | AC11: =AVERAGE(D11:Q11) -> 106.63571 | AD11: =AVERAGE(R11:T11) -> 107.83333 | AE11: 100.5 | AF11: 106.5 | AG11: =AVERAGE(U11:Z11) -> 104.6 | AH11: =SUM(AC11:AG11) -> 526.06905 | AI11: =AC11/$AH$2*100 -> 20.447137 | AJ11: =AD11/$AH$2*100 -> 20.676778 | AK11: =AE11/$AH$2*100 -> 19.270629 | AL11: =AF11/$AH$2*100 -> 20.421114 | AM11: =AG11/$AH$2*100 -> 20.056794
A12: Urban | B12: 2013 | C12: April | D12: 114.6 | E12: 113.4 | F12: 106 | G12: 104.7 | H12: 102.1 | I12: 109.5 | J12: 109.7 | K12: 104.6 | L12: 102 | M12: 103.5 | N12: 108.2 | O12: 110.6 | P12: 108.8 | Q12: 108.5 | R12: 107.9 | S12: 106.4 | T12: 107.7 | U12: 106.5 | V12: 105.7 | W12: 105 | X12: 104 | Y12: 105.2 | Z12: 103.2 | AA12: 105.1 | AB12: 105.7 | AC12: =AVERAGE(D12:Q12) -> 107.58571 | AD12: =AVERAGE(R12:T12) -> 107.33333 | AE12: 100.5 | AF12: 106.4 | AG12: =AVERAGE(U12:Z12) -> 104.93333 | AH12: =SUM(AC12:AG12) -> 526.75238 | AI12: =AC12/$AH$2*100 -> 20.629297 | AJ12: =AD12/$AH$2*100 -> 20.580904 | AK12: =AE12/$AH$2*100 -> 19.270629 | AL12: =AF12/$AH$2*100 -> 20.401939 | AM12: =AG12/$AH$2*100 -> 20.12071
A13: Rural+Urban | B13: 2013 | C13: April | D13: 111.6 | E13: 110.9 | F13: 106.6 | G13: 105.7 | H13: 104.4 | I13: 108.9 | J13: 105.5 | K13: 105.3 | L13: 103.5 | M13: 103.3 | N13: 107.2 | O13: 109.6 | P13: 107.7 | Q13: 107.5 | R13: 108 | S13: 107 | T13: 107.9 | U13: 106.3 | V13: 105.3 | W13: 104.7 | X13: 104.2 | Y13: 105 | Z13: 102.9 | AA13: 104.8 | AB13: 106.1 | AC13: =AVERAGE(D13:Q13) -> 106.97857 | AD13: =AVERAGE(R13:T13) -> 107.63333 | AE13: 100.5 | AF13: 106.5 | AG13: =AVERAGE(U13:Z13) -> 104.73333 | AH13: =SUM(AC13:AG13) -> 526.34524 | AI13: =AC13/$AH$2*100 -> 20.512879 | AJ13: =AD13/$AH$2*100 -> 20.638428 | AK13: =AE13/$AH$2*100 -> 19.270629 | AL13: =AF13/$AH$2*100 -> 20.421114 | AM13: =AG13/$AH$2*100 -> 20.08236
... A373: Rural+Urban | B373: 2023 | C373: May | D373: 173.7 | E373: 214.3 | F373: 173.2 | G373: 179.5 | H373: 170 | I373: 172.2 | J373: 161 | K373: 175.6 | L373: 122.7 | M373: 218 | N373: 173.4 | O373: 194.2 | P373: 179.1 | Q373: 201 | R373: 187.3 | S373: 179.7 | T373: 186.2 | U373: 175.2 | V373: 185.7 | W373: 164.8 | X373: 171.2 | Y373: 177.1 | Z373: 185.2 | AA373: 175.7 | AB373: 179.1 | AC373: =AVERAGE(D373:Q373) -> 179.13571 | AD373: =AVERAGE(R373:T373) -> 184.4 | AE373: 175.6 | AF373: 182.8 | AG373: =AVERAGE(U373:Z373) -> 176.53333 | AH373: =SUM(AC373:AG373) -> 898.46905 | AI373: =AC373/$AH$2*100 -> 34.348834 | AJ373: =AD373/$AH$2*100 -> 35.358248 | AK373: =AE373/$AH$2*100 -> 33.67087 | AL373: =AF373/$AH$2*100 -> 35.051452 | AM373: =AG373/$AH$2*100 -> 33.849834
